File: Peptide_dh/IFABEW/Detail-IFABEW-D3.txt
IFABEW-D3  0/ 0
Eng:  -8684.0003 -> -8684.0003, dE: 0.0000
fmax: 0.00099
time: 1410.2
Strain 0.000 0.000 -0.020 0.000 0.000 0.000
Stress (GPa) -0.14 -0.14 -0.31 0.00 -0.00 0.00

IFABEW-D3  0/ 1
Eng:  -8684.0397 -> -8684.0397, dE: 0.0000
fmax: 0.00078
time: 518.5
Strain 0.000 0.000 -0.010 0.000 0.000 0.000
Stress (GPa) -0.09 -0.09 -0.17 0.00 -0.00 0.00

IFABEW-D3  0/ 2
Eng:  -8684.0530 -> -8684.0530, dE: 0.0000
fmax: 0.00082
time: 6.4
Strain 0.000 0.000 0.000 0.000 0.000 0.000
Stress (GPa) 0.00 0.00 0.00 0.00 0.00 0.00

IFABEW-D3  0/ 3
Eng:  -8684.0411 -> -8684.0411, dE: 0.0000
fmax: 0.00057
time: 502.9
Strain 0.000 0.000 0.010 0.000 0.000 0.000
Stress (GPa) 0.08 0.08 0.16 -0.00 0.00 0.00

IFABEW-D3  0/ 4
Eng:  -8684.0044 -> -8684.0044, dE: 0.0000
fmax: 0.00098
time: 534.8
Strain 0.000 0.000 0.020 0.000 0.000 0.000
Stress (GPa) 0.16 0.16 0.30 -0.00 -0.00 0.00

IFABEW-D3  1/ 0
Eng:  -8683.9946 -> -8683.9946, dE: 0.0000
fmax: 0.00091
time: 701.3
Strain -0.020 0.000 0.000 -0.020 0.000 0.000
Stress (GPa) -0.29 -0.22 -0.16 -0.07 0.00 0.00

IFABEW-D3  1/ 1
Eng:  -8684.0377 -> -8684.0377, dE: 0.0000
fmax: 0.00088
time: 513.2
Strain -0.010 0.000 0.000 -0.010 0.000 0.000
Stress (GPa) -0.16 -0.12 -0.08 -0.04 0.00 0.00

IFABEW-D3  1/ 2
Eng:  -8684.0530 -> -8684.0530, dE: 0.0000
fmax: 0.00082
time: 6.0
Strain 0.000 0.000 0.000 0.000 0.000 0.000
Stress (GPa) 0.00 0.00 0.00 0.00 0.00 0.00

IFABEW-D3  1/ 3
Eng:  -8684.0406 -> -8684.0406, dE: 0.0000
fmax: 0.00076
time: 563.2
Strain 0.010 0.000 0.000 0.010 0.000 0.000
Stress (GPa) 0.14 0.10 0.07 0.04 0.00 0.00

IFABEW-D3  1/ 4
Eng:  -8684.0007 -> -8684.0007, dE: 0.0000
fmax: 0.00096
time: 771.8
Strain 0.020 0.000 0.000 0.020 0.000 0.000
Stress (GPa) 0.27 0.20 0.15 0.07 0.00 0.00

IFABEW-D3  2/ 0
Eng:  -8684.0043 -> -8684.0043, dE: 0.0000
fmax: 0.00096
time: 575.4
Strain -0.020 0.000 0.000 0.000 0.000 0.000
Stress (GPa) -0.30 -0.22 -0.16 -0.00 0.00 -0.00

IFABEW-D3  2/ 1
Eng:  -8684.0401 -> -8684.0401, dE: 0.0000
fmax: 0.00097
time: 414.8
Strain -0.010 0.000 0.000 0.000 0.000 0.000
Stress (GPa) -0.17 -0.12 -0.09 -0.00 -0.00 0.00

IFABEW-D3  2/ 2
Eng:  -8684.0530 -> -8684.0530, dE: 0.0000
fmax: 0.00082
time: 5.7
Strain 0.000 0.000 0.000 0.000 0.000 0.000
Stress (GPa) 0.00 0.00 0.00 0.00 0.00 0.00

IFABEW-D3  2/ 3
Eng:  -8684.0429 -> -8684.0429, dE: 0.0000
fmax: 0.00095
time: 458.6
Strain 0.010 0.000 0.000 0.000 0.000 0.000
Stress (GPa) 0.14 0.10 0.08 0.00 -0.00 0.00

IFABEW-D3  2/ 4
Eng:  -8684.0110 -> -8684.0110, dE: 0.0000
fmax: 0.00078
time: 589.9
Strain 0.020 0.000 0.000 0.000 0.000 0.000
Stress (GPa) 0.27 0.19 0.15 0.00 0.00 0.00

IFABEW-D3  3/ 0
Eng:  -8683.9887 -> -8683.9887, dE: 0.0000
fmax: 0.00060
time: 884.3
Strain 0.000 0.000 -0.020 -0.020 0.000 0.000
Stress (GPa) -0.15 -0.15 -0.32 -0.07 0.00 0.00

IFABEW-D3  3/ 1
Eng:  -8684.0369 -> -8684.0369, dE: 0.0000
fmax: 0.00082
time: 556.3
Strain 0.000 0.000 -0.010 -0.010 0.000 0.000
Stress (GPa) -0.08 -0.08 -0.17 -0.04 -0.00 0.00

IFABEW-D3  3/ 2
Eng:  -8684.0530 -> -8684.0530, dE: 0.0000
fmax: 0.00082
time: 5.8
Strain 0.000 0.000 0.000 0.000 0.000 0.000
Stress (GPa) 0.00 0.00 0.00 0.00 0.00 0.00

IFABEW-D3  3/ 3
Eng:  -8684.0386 -> -8684.0386, dE: 0.0000
fmax: 0.00095
time: 614.2
Strain 0.000 0.000 0.010 0.010 0.000 0.000
Stress (GPa) 0.07 0.07 0.15 0.03 -0.00 0.00

IFABEW-D3  3/ 4
Eng:  -8683.9946 -> -8683.9946, dE: 0.0000
fmax: 0.00096
time: 684.0
Strain 0.000 0.000 0.020 0.020 0.000 0.000
Stress (GPa) 0.15 0.15 0.29 0.07 -0.00 0.00