File: Peptide_dh/IFABEW/Detail-IFABEW-TS.txt
IFABEW-TS  0/ 0
Eng:  -8676.5621 -> -8676.5621, dE: 0.0000
fmax: 0.00089
time: 1205.3
Strain 0.000 0.000 -0.020 0.000 0.000 0.000
Stress (GPa) -0.15 -0.16 -0.35 -0.00 0.00 0.01

IFABEW-TS  0/ 1
Eng:  -8676.6065 -> -8676.6065, dE: 0.0000
fmax: 0.00078
time: 433.4
Strain 0.000 0.000 -0.010 0.000 0.000 0.000
Stress (GPa) -0.09 -0.10 -0.19 -0.00 0.00 0.01

IFABEW-TS  0/ 2
Eng:  -8676.6232 -> -8676.6232, dE: 0.0000
fmax: 0.00094
time: 5.5
Strain 0.000 0.000 0.000 0.000 0.000 0.000
Stress (GPa) -0.01 -0.01 -0.01 -0.00 0.00 0.00

IFABEW-TS  0/ 3
Eng:  -8676.6140 -> -8676.6140, dE: 0.0000
fmax: 0.00093
time: 395.5
Strain 0.000 0.000 0.010 0.000 0.000 0.000
Stress (GPa) 0.07 0.06 0.14 -0.00 0.00 0.01

IFABEW-TS  0/ 4
Eng:  -8676.5820 -> -8676.5820, dE: 0.0000
fmax: 0.00086
time: 475.6
Strain 0.000 0.000 0.020 0.000 0.000 0.000
Stress (GPa) 0.14 0.13 0.26 -0.00 0.00 0.01

IFABEW-TS  1/ 0
Eng:  -8676.5613 -> -8676.5613, dE: 0.0000
fmax: 0.00086
time: 605.0
Strain -0.020 0.000 0.000 -0.020 0.000 0.000
Stress (GPa) -0.29 -0.23 -0.17 -0.07 0.00 0.01

IFABEW-TS  1/ 1
Eng:  -8676.6064 -> -8676.6064, dE: 0.0000
fmax: 0.00089
time: 450.1
Strain -0.010 0.000 0.000 -0.010 0.000 0.000
Stress (GPa) -0.15 -0.12 -0.10 -0.04 -0.00 0.01

IFABEW-TS  1/ 2
Eng:  -8676.6232 -> -8676.6232, dE: 0.0000
fmax: 0.00094
time: 5.4
Strain 0.000 0.000 0.000 0.000 0.000 0.000
Stress (GPa) -0.01 -0.01 -0.01 -0.00 0.00 0.00

IFABEW-TS  1/ 3
Eng:  -8676.6122 -> -8676.6122, dE: 0.0000
fmax: 0.00086
time: 438.0
Strain 0.010 0.000 0.000 0.010 0.000 0.000
Stress (GPa) 0.12 0.08 0.06 0.03 0.00 0.01

IFABEW-TS  1/ 4
Eng:  -8676.5752 -> -8676.5752, dE: 0.0000
fmax: 0.00092
time: 558.5
Strain 0.020 0.000 0.000 0.020 0.000 0.000
Stress (GPa) 0.24 0.16 0.12 0.07 0.00 0.01

IFABEW-TS  2/ 0
Eng:  -8676.5727 -> -8676.5727, dE: 0.0000
fmax: 0.00096
time: 513.7
Strain -0.020 0.000 0.000 0.000 0.000 0.000
Stress (GPa) -0.29 -0.23 -0.17 0.00 -0.00 0.01

IFABEW-TS  2/ 1
Eng:  -8676.6091 -> -8676.6091, dE: 0.0000
fmax: 0.00098
time: 389.5
Strain -0.010 0.000 0.000 0.000 0.000 0.000
Stress (GPa) -0.16 -0.12 -0.10 -0.00 0.00 0.01

IFABEW-TS  2/ 2
Eng:  -8676.6232 -> -8676.6232, dE: 0.0000
fmax: 0.00094
time: 6.2
Strain 0.000 0.000 0.000 0.000 0.000 0.000
Stress (GPa) -0.01 -0.01 -0.01 -0.00 0.00 0.00

IFABEW-TS  2/ 3
Eng:  -8676.6150 -> -8676.6150, dE: 0.0000
fmax: 0.00080
time: 380.5
Strain 0.010 0.000 0.000 0.000 0.000 0.000
Stress (GPa) 0.12 0.08 0.06 -0.00 0.00 0.01

IFABEW-TS  2/ 4
Eng:  -8676.5861 -> -8676.5861, dE: 0.0000
fmax: 0.00096
time: 510.7
Strain 0.020 0.000 0.000 0.000 0.000 0.000
Stress (GPa) 0.24 0.16 0.12 -0.00 0.00 0.01

IFABEW-TS  3/ 0
Eng:  -8676.5495 -> -8676.5495, dE: 0.0000
fmax: 0.00045
time: 844.5
Strain 0.000 0.000 -0.020 -0.020 0.000 0.000
Stress (GPa) -0.16 -0.17 -0.36 -0.07 -0.00 0.01

IFABEW-TS  3/ 1
Eng:  -8676.6037 -> -8676.6037, dE: 0.0000
fmax: 0.00089
time: 496.3
Strain 0.000 0.000 -0.010 -0.010 0.000 0.000
Stress (GPa) -0.09 -0.10 -0.18 -0.04 -0.00 0.01

IFABEW-TS  3/ 2
Eng:  -8676.6232 -> -8676.6232, dE: 0.0000
fmax: 0.00094
time: 5.4
Strain 0.000 0.000 0.000 0.000 0.000 0.000
Stress (GPa) -0.01 -0.01 -0.01 -0.00 0.00 0.00

IFABEW-TS  3/ 3
Eng:  -8676.6113 -> -8676.6113, dE: 0.0000
fmax: 0.00077
time: 478.2
Strain 0.000 0.000 0.010 0.010 0.000 0.000
Stress (GPa) 0.06 0.06 0.13 0.04 0.00 0.01

IFABEW-TS  3/ 4
Eng:  -8676.5711 -> -8676.5711, dE: 0.0000
fmax: 0.00098
time: 615.0
Strain 0.000 0.000 0.020 0.020 0.000 0.000
Stress (GPa) 0.13 0.12 0.25 0.07 0.00 0.01