File: Peptide_dh/HIZCOJ/Detail-HIZCOJ-TS.txt
HIZCOJ-TS  0/ 0
Eng:  -9672.9149 -> -9672.9149, dE: 0.0000
fmax: 0.00089
time: 740.7
Strain -0.020 0.000 0.000 -0.020 0.000 0.000
Stress (GPa) -0.32 -0.13 -0.11 -0.13 -0.00 0.00

HIZCOJ-TS  0/ 1
Eng:  -9672.9708 -> -9672.9708, dE: 0.0000
fmax: 0.00090
time: 295.1
Strain -0.010 0.000 0.000 -0.010 0.000 0.000
Stress (GPa) -0.11 -0.02 0.01 -0.07 0.00 0.00

HIZCOJ-TS  0/ 2
Eng:  -9672.9791 -> -9672.9791, dE: 0.0000
fmax: 0.00098
time: 84.0
Strain 0.000 0.000 0.000 0.000 0.000 0.000
Stress (GPa) 0.10 0.10 0.10 -0.00 -0.00 0.00

HIZCOJ-TS  0/ 3
Eng:  -9672.9416 -> -9672.9416, dE: 0.0000
fmax: 0.00089
time: 254.2
Strain 0.010 0.000 0.000 0.010 0.000 0.000
Stress (GPa) 0.29 0.19 0.20 0.07 0.00 0.00

HIZCOJ-TS  0/ 4
Eng:  -9672.8609 -> -9672.8609, dE: 0.0000
fmax: 0.00099
time: 596.3
Strain 0.020 0.000 0.000 0.020 0.000 0.000
Stress (GPa) 0.46 0.25 0.29 0.13 -0.00 0.00

HIZCOJ-TS  1/ 0
Eng:  -9672.9418 -> -9672.9418, dE: 0.0000
fmax: 0.00098
time: 946.3
Strain 0.000 -0.020 0.000 0.000 -0.020 0.000
Stress (GPa) -0.09 -0.22 -0.08 -0.00 -0.02 0.00

HIZCOJ-TS  1/ 1
Eng:  -9672.9754 -> -9672.9754, dE: 0.0000
fmax: 0.00099
time: 421.8
Strain 0.000 -0.010 0.000 0.000 -0.010 0.000
Stress (GPa) -0.00 -0.09 0.02 0.00 -0.02 0.00

HIZCOJ-TS  1/ 2
Eng:  -9672.9791 -> -9672.9791, dE: 0.0000
fmax: 0.00098
time: 29.0
Strain 0.000 0.000 0.000 0.000 0.000 0.000
Stress (GPa) 0.10 0.10 0.10 -0.00 -0.00 0.00

HIZCOJ-TS  1/ 3
Eng:  -9672.9516 -> -9672.9516, dE: 0.0000
fmax: 0.00096
time: 374.4
Strain 0.000 0.010 0.000 0.000 0.010 0.000
Stress (GPa) 0.18 0.24 0.19 0.00 0.02 0.00

HIZCOJ-TS  1/ 4
Eng:  -9672.8921 -> -9672.8921, dE: 0.0000
fmax: 0.00099
time: 445.5
Strain 0.000 0.020 0.000 0.000 0.020 0.000
Stress (GPa) 0.26 0.38 0.25 0.00 0.04 0.00

HIZCOJ-TS  2/ 0
Eng:  -9672.9197 -> -9672.9197, dE: 0.0000
fmax: 0.00093
time: 498.6
Strain 0.000 0.000 -0.020 0.000 0.000 -0.020
Stress (GPa) -0.10 -0.09 -0.33 -0.00 0.00 -0.13

HIZCOJ-TS  2/ 1
Eng:  -9672.9742 -> -9672.9742, dE: 0.0000
fmax: 0.00097
time: 351.3
Strain 0.000 0.000 -0.010 0.000 0.000 -0.010
Stress (GPa) -0.00 0.00 -0.10 0.00 0.00 -0.07

HIZCOJ-TS  2/ 2
Eng:  -9672.9791 -> -9672.9791, dE: 0.0000
fmax: 0.00098
time: 239.5
Strain 0.000 0.000 0.000 0.000 0.000 0.000
Stress (GPa) 0.10 0.10 0.10 -0.00 -0.00 0.00

HIZCOJ-TS  2/ 3
Eng:  -9672.9405 -> -9672.9405, dE: 0.0000
fmax: 0.00098
time: 515.4
Strain 0.000 0.000 0.010 0.000 0.000 0.010
Stress (GPa) 0.19 0.16 0.29 0.00 0.00 0.06

HIZCOJ-TS  2/ 4
Eng:  -9672.8695 -> -9672.8695, dE: 0.0000
fmax: 0.00060
time: 556.7
Strain 0.000 0.000 0.020 0.000 0.000 0.020
Stress (GPa) 0.30 0.25 0.37 0.00 0.00 0.10