File: Peptide_dh/HIZCOJ/Detail-HIZCOJ-D3.txt
HIZCOJ-D3  0/ 0
Eng:  -9682.1678 -> -9682.1678, dE: 0.0000
fmax: 0.00100
time: 1682.0
Strain -0.020 0.000 0.000 -0.020 0.000 0.000
Stress (GPa) -0.49 -0.31 -0.27 0.01 -0.00 -0.00

HIZCOJ-D3  0/ 1
Eng:  -9682.2216 -> -9682.2216, dE: 0.0000
fmax: 0.00099
time: 435.3
Strain -0.010 0.000 0.000 -0.010 0.000 0.000
Stress (GPa) -0.27 -0.14 -0.14 -0.03 -0.00 0.00

HIZCOJ-D3  0/ 2
Eng:  -9682.2441 -> -9682.2441, dE: 0.0000
fmax: 0.00097
time: 94.0
Strain 0.000 0.000 0.000 0.000 0.000 0.000
Stress (GPa) 0.00 -0.00 0.00 0.00 -0.00 0.00

HIZCOJ-D3  0/ 3
Eng:  -9682.2223 -> -9682.2223, dE: 0.0000
fmax: 0.00096
time: 397.4
Strain 0.010 0.000 0.000 0.010 0.000 0.000
Stress (GPa) 0.25 0.11 0.15 0.04 -0.00 -0.00

HIZCOJ-D3  0/ 4
Eng:  -9682.1561 -> -9682.1561, dE: 0.0000
fmax: 0.00087
time: 473.3
Strain 0.020 0.000 0.000 0.020 0.000 0.000
Stress (GPa) 0.48 0.20 0.28 0.07 -0.00 0.00

HIZCOJ-D3  1/ 0
Eng:  -9682.1736 -> -9682.1736, dE: 0.0000
fmax: 0.00072
time: 624.0
Strain 0.000 -0.020 0.000 0.000 -0.020 0.000
Stress (GPa) -0.28 -0.32 -0.19 -0.00 -0.14 0.00

HIZCOJ-D3  1/ 1
Eng:  -9682.2267 -> -9682.2267, dE: 0.0000
fmax: 0.00089
time: 489.5
Strain 0.000 -0.010 0.000 0.000 -0.010 0.000
Stress (GPa) -0.13 -0.16 -0.09 -0.00 -0.07 -0.00

HIZCOJ-D3  1/ 2
Eng:  -9682.2441 -> -9682.2441, dE: 0.0000
fmax: 0.00097
time: 236.3
Strain 0.000 0.000 0.000 0.000 0.000 0.000
Stress (GPa) 0.00 -0.00 0.00 0.00 -0.00 0.00

HIZCOJ-D3  1/ 3
Eng:  -9682.2324 -> -9682.2324, dE: 0.0000
fmax: 0.00089
time: 728.6
Strain 0.000 0.010 0.000 0.000 0.010 0.000
Stress (GPa) 0.11 0.15 0.11 -0.00 0.06 -0.00

HIZCOJ-D3  1/ 4
Eng:  -9682.1972 -> -9682.1972, dE: 0.0000
fmax: 0.00093
time: 909.1
Strain 0.000 0.020 0.000 0.000 0.020 0.000
Stress (GPa) 0.21 0.27 0.23 -0.00 0.12 -0.00

HIZCOJ-D3  2/ 0
Eng:  -9682.1683 -> -9682.1683, dE: 0.0000
fmax: 0.00097
time: 609.6
Strain 0.000 0.000 -0.020 0.000 0.000 -0.020
Stress (GPa) -0.29 -0.21 -0.46 0.00 0.00 -0.05

HIZCOJ-D3  2/ 1
Eng:  -9682.2236 -> -9682.2236, dE: 0.0000
fmax: 0.00098
time: 504.2
Strain 0.000 0.000 -0.010 0.000 0.000 -0.010
Stress (GPa) -0.15 -0.11 -0.25 0.00 -0.00 -0.05

HIZCOJ-D3  2/ 2
Eng:  -9682.2441 -> -9682.2441, dE: 0.0000
fmax: 0.00097
time: 57.2
Strain 0.000 0.000 0.000 0.000 0.000 0.000
Stress (GPa) 0.00 -0.00 0.00 0.00 -0.00 0.00

HIZCOJ-D3  2/ 3
Eng:  -9682.2191 -> -9682.2191, dE: 0.0000
fmax: 0.00087
time: 380.0
Strain 0.000 0.000 0.010 0.000 0.000 0.010
Stress (GPa) 0.14 0.09 0.26 -0.00 -0.00 0.06

HIZCOJ-D3  2/ 4
Eng:  -9682.1477 -> -9682.1477, dE: 0.0000
fmax: 0.00094
time: 510.0
Strain 0.000 0.000 0.020 0.000 0.000 0.020
Stress (GPa) 0.27 0.15 0.50 0.00 -0.00 0.10