File: Peptide/IFABEW/Detail-IFABEW-D3.txt
IFABEW-D3  0/ 0
Eng:  -10021.3975 -> -10021.3975, dE: 0.0000
fmax: 0.00087
time: 1388.0
Strain 0.000 0.000 -0.020 0.000 0.000 0.000
Stress (GPa) -0.20 -0.21 -0.32 -0.00 -0.02 0.01

IFABEW-D3  0/ 1
Eng:  -10021.4347 -> -10021.4347, dE: 0.0000
fmax: 0.00090
time: 469.2
Strain 0.000 0.000 -0.010 0.000 0.000 0.000
Stress (GPa) -0.10 -0.11 -0.17 -0.00 -0.01 0.01

IFABEW-D3  0/ 2
Eng:  -10021.4468 -> -10021.4468, dE: 0.0000
fmax: 0.00099
time: 172.8
Strain 0.000 0.000 0.000 0.000 0.000 0.000
Stress (GPa) 0.00 0.00 -0.00 0.00 0.00 -0.00

IFABEW-D3  0/ 3
Eng:  -10021.4355 -> -10021.4355, dE: 0.0000
fmax: 0.00086
time: 397.2
Strain 0.000 0.000 0.010 0.000 0.000 0.000
Stress (GPa) 0.10 0.09 0.16 -0.00 0.01 0.01

IFABEW-D3  0/ 4
Eng:  -10021.4034 -> -10021.4034, dE: 0.0000
fmax: 0.00097
time: 565.1
Strain 0.000 0.000 0.020 0.000 0.000 0.000
Stress (GPa) 0.17 0.18 0.28 -0.00 0.02 0.01

IFABEW-D3  1/ 0
Eng:  -10021.3856 -> -10021.3856, dE: 0.0000
fmax: 0.00079
time: 708.2
Strain -0.020 0.000 0.000 -0.020 0.000 0.000
Stress (GPa) -0.34 -0.27 -0.22 -0.08 -0.02 0.04

IFABEW-D3  1/ 1
Eng:  -10021.4322 -> -10021.4322, dE: 0.0000
fmax: 0.00099
time: 822.1
Strain -0.010 0.000 0.000 -0.010 0.000 0.000
Stress (GPa) -0.17 -0.13 -0.10 -0.04 -0.01 0.02

IFABEW-D3  1/ 2
Eng:  -10021.4468 -> -10021.4468, dE: 0.0000
fmax: 0.00099
time: 45.2
Strain 0.000 0.000 0.000 0.000 0.000 0.000
Stress (GPa) 0.00 0.00 -0.00 0.00 0.00 -0.00

IFABEW-D3  1/ 3
Eng:  -10021.4387 -> -10021.4387, dE: 0.0000
fmax: 0.00097
time: 731.8
Strain 0.010 0.000 0.000 0.010 0.000 0.000
Stress (GPa) 0.11 0.08 0.08 0.03 0.02 -0.00

IFABEW-D3  1/ 4
Eng:  -10021.4595 -> -10021.4595, dE: 0.0000
fmax: 0.00674
time: 1245.6
Strain 0.020 0.000 0.000 0.020 0.000 0.000
Stress (GPa) 0.19 0.18 0.16 -0.00 0.07 -0.01

IFABEW-D3  2/ 0
Eng:  -10021.3977 -> -10021.3977, dE: 0.0000
fmax: 0.00085
time: 649.6
Strain -0.020 0.000 0.000 0.000 0.000 0.000
Stress (GPa) -0.34 -0.26 -0.21 0.01 -0.02 0.03

IFABEW-D3  2/ 1
Eng:  -10021.4344 -> -10021.4344, dE: 0.0000
fmax: 0.00079
time: 677.8
Strain -0.010 0.000 0.000 0.000 0.000 0.000
Stress (GPa) -0.17 -0.13 -0.10 0.01 -0.01 0.02

IFABEW-D3  2/ 2
Eng:  -10021.4468 -> -10021.4468, dE: 0.0000
fmax: 0.00099
time: 19.3
Strain 0.000 0.000 0.000 0.000 0.000 0.000
Stress (GPa) 0.00 0.00 -0.00 0.00 0.00 -0.00

IFABEW-D3  2/ 3
Eng:  -10021.4395 -> -10021.4395, dE: 0.0000
fmax: 0.00097
time: 616.8
Strain 0.010 0.000 0.000 0.000 0.000 0.000
Stress (GPa) 0.13 0.09 0.08 -0.01 0.02 -0.00

IFABEW-D3  2/ 4
Eng:  -10021.4458 -> -10021.4458, dE: 0.0000
fmax: 0.00492
time: 1241.9
Strain 0.020 0.000 0.000 0.000 0.000 0.000
Stress (GPa) 0.18 0.26 0.17 -0.02 0.05 -0.04

IFABEW-D3  3/ 0
Eng:  -10021.3821 -> -10021.3821, dE: 0.0000
fmax: 0.00097
time: 1312.5
Strain 0.000 0.000 -0.020 -0.020 0.000 0.000
Stress (GPa) -0.21 -0.20 -0.33 -0.10 -0.02 0.01

IFABEW-D3  3/ 1
Eng:  -10021.4314 -> -10021.4314, dE: 0.0000
fmax: 0.00096
time: 676.2
Strain 0.000 0.000 -0.010 -0.010 0.000 0.000
Stress (GPa) -0.10 -0.11 -0.16 -0.05 -0.01 0.01

IFABEW-D3  3/ 2
Eng:  -10021.4468 -> -10021.4468, dE: 0.0000
fmax: 0.00099
time: 65.7
Strain 0.000 0.000 0.000 0.000 0.000 0.000
Stress (GPa) 0.00 0.00 -0.00 0.00 0.00 -0.00

IFABEW-D3  3/ 3
Eng:  -10021.4338 -> -10021.4338, dE: 0.0000
fmax: 0.00092
time: 677.7
Strain 0.000 0.000 0.010 0.010 0.000 0.000
Stress (GPa) 0.07 0.08 0.14 0.03 0.01 0.01

IFABEW-D3  3/ 4
Eng:  -10021.4227 -> -10021.4227, dE: 0.0000
fmax: 0.01029
time: 1316.7
Strain 0.000 0.000 0.020 0.020 0.000 0.000
Stress (GPa) 0.08 0.08 0.26 -0.01 0.04 0.03