File: Peptide/IFABEW/Detail-IFABEW-TS.txt
IFABEW-TS  0/ 0
Eng:  -10013.0384 -> -10013.0384, dE: 0.0000
fmax: 0.00097
time: 1440.8
Strain 0.000 0.000 -0.020 0.000 0.000 0.000
Stress (GPa) -0.16 -0.17 -0.33 0.00 0.00 0.01

IFABEW-TS  0/ 1
Eng:  -10013.0768 -> -10013.0768, dE: 0.0000
fmax: 0.00096
time: 507.3
Strain 0.000 0.000 -0.010 0.000 0.000 0.000
Stress (GPa) -0.09 -0.10 -0.18 0.00 0.00 0.01

IFABEW-TS  0/ 2
Eng:  -10013.0909 -> -10013.0909, dE: 0.0000
fmax: 0.00098
time: 6.4
Strain 0.000 0.000 0.000 0.000 0.000 0.000
Stress (GPa) 0.00 -0.00 0.00 -0.00 -0.00 0.00

IFABEW-TS  0/ 3
Eng:  -10013.0783 -> -10013.0783, dE: 0.0000
fmax: 0.00100
time: 481.9
Strain 0.000 0.000 0.010 0.000 0.000 0.000
Stress (GPa) 0.10 0.09 0.18 0.00 0.00 0.01

IFABEW-TS  0/ 4
Eng:  -10013.0404 -> -10013.0404, dE: 0.0000
fmax: 0.00096
time: 594.4
Strain 0.000 0.000 0.020 0.000 0.000 0.000
Stress (GPa) 0.19 0.18 0.32 0.00 0.00 0.01

IFABEW-TS  1/ 0
Eng:  -10013.0239 -> -10013.0239, dE: 0.0000
fmax: 0.00096
time: 725.3
Strain -0.020 0.000 0.000 -0.020 0.000 0.000
Stress (GPa) -0.32 -0.22 -0.18 -0.09 -0.00 0.01

IFABEW-TS  1/ 1
Eng:  -10013.0742 -> -10013.0742, dE: 0.0000
fmax: 0.00094
time: 687.6
Strain -0.010 0.000 0.000 -0.010 0.000 0.000
Stress (GPa) -0.16 -0.11 -0.09 -0.04 -0.00 0.01

IFABEW-TS  1/ 2
Eng:  -10013.0909 -> -10013.0909, dE: 0.0000
fmax: 0.00098
time: 6.5
Strain 0.000 0.000 0.000 0.000 0.000 0.000
Stress (GPa) 0.00 -0.00 0.00 -0.00 -0.00 0.00

IFABEW-TS  1/ 3
Eng:  -10013.0764 -> -10013.0764, dE: 0.0000
fmax: 0.00100
time: 533.1
Strain 0.010 0.000 0.000 0.010 0.000 0.000
Stress (GPa) 0.16 0.10 0.09 0.04 0.00 0.01

IFABEW-TS  1/ 4
Eng:  -10013.0312 -> -10013.0312, dE: 0.0000
fmax: 0.00097
time: 671.2
Strain 0.020 0.000 0.000 0.020 0.000 0.000
Stress (GPa) 0.30 0.19 0.17 0.08 0.00 0.01

IFABEW-TS  2/ 0
Eng:  -10013.0378 -> -10013.0378, dE: 0.0000
fmax: 0.00097
time: 669.5
Strain -0.020 0.000 0.000 0.000 0.000 0.000
Stress (GPa) -0.33 -0.22 -0.18 -0.00 0.00 0.01

IFABEW-TS  2/ 1
Eng:  -10013.0764 -> -10013.0764, dE: 0.0000
fmax: 0.00098
time: 471.1
Strain -0.010 0.000 0.000 0.000 0.000 0.000
Stress (GPa) -0.17 -0.12 -0.10 0.00 0.00 0.01

IFABEW-TS  2/ 2
Eng:  -10013.0909 -> -10013.0909, dE: 0.0000
fmax: 0.00098
time: 6.4
Strain 0.000 0.000 0.000 0.000 0.000 0.000
Stress (GPa) 0.00 -0.00 0.00 -0.00 -0.00 0.00

IFABEW-TS  2/ 3
Eng:  -10013.0795 -> -10013.0795, dE: 0.0000
fmax: 0.00093
time: 440.4
Strain 0.010 0.000 0.000 0.000 0.000 0.000
Stress (GPa) 0.16 0.10 0.10 0.00 0.00 0.01

IFABEW-TS  2/ 4
Eng:  -10013.0440 -> -10013.0440, dE: 0.0000
fmax: 0.00099
time: 587.6
Strain 0.020 0.000 0.000 0.000 0.000 0.000
Stress (GPa) 0.31 0.19 0.18 -0.00 -0.00 0.01

IFABEW-TS  3/ 0
Eng:  -10013.0234 -> -10013.0234, dE: 0.0000
fmax: 0.00091
time: 885.5
Strain 0.000 0.000 -0.020 -0.020 0.000 0.000
Stress (GPa) -0.16 -0.17 -0.33 -0.09 -0.00 0.01

IFABEW-TS  3/ 1
Eng:  -10013.0747 -> -10013.0747, dE: 0.0000
fmax: 0.00081
time: 795.6
Strain 0.000 0.000 -0.010 -0.010 0.000 0.000
Stress (GPa) -0.08 -0.09 -0.16 -0.04 -0.00 0.01

IFABEW-TS  3/ 2
Eng:  -10013.0909 -> -10013.0909, dE: 0.0000
fmax: 0.00098
time: 6.3
Strain 0.000 0.000 0.000 0.000 0.000 0.000
Stress (GPa) 0.00 -0.00 0.00 -0.00 -0.00 0.00

IFABEW-TS  3/ 3
Eng:  -10013.0753 -> -10013.0753, dE: 0.0000
fmax: 0.00092
time: 674.4
Strain 0.000 0.000 0.010 0.010 0.000 0.000
Stress (GPa) 0.09 0.09 0.17 0.04 0.00 0.01

IFABEW-TS  3/ 4
Eng:  -10013.0273 -> -10013.0273, dE: 0.0000
fmax: 0.00094
time: 890.3
Strain 0.000 0.000 0.020 0.020 0.000 0.000
Stress (GPa) 0.18 0.17 0.31 0.08 0.00 0.01