File: Peptide/HIZCOJ/Detail-HIZCOJ-TS.txt
HIZCOJ-TS  0/ 0
Eng:  -11904.3818 -> -11904.3818, dE: 0.0000
fmax: 0.00099
time: 1120.8
Strain -0.020 0.000 0.000 -0.020 0.000 0.000
Stress (GPa) -0.29 -0.21 -0.15 -0.12 -0.00 0.00

HIZCOJ-TS  0/ 1
Eng:  -11904.4387 -> -11904.4387, dE: 0.0000
fmax: 0.00092
time: 414.1
Strain -0.010 0.000 0.000 -0.010 0.000 0.000
Stress (GPa) -0.14 -0.07 -0.03 -0.06 -0.00 -0.00

HIZCOJ-TS  0/ 2
Eng:  -11904.4536 -> -11904.4536, dE: 0.0000
fmax: 0.00092
time: 3.8
Strain 0.000 0.000 0.000 0.000 0.000 0.000
Stress (GPa) 0.08 0.07 0.08 -0.00 -0.00 0.00

HIZCOJ-TS  0/ 3
Eng:  -11904.4267 -> -11904.4267, dE: 0.0000
fmax: 0.00097
time: 489.5
Strain 0.010 0.000 0.000 0.010 0.000 0.000
Stress (GPa) 0.24 0.19 0.19 0.06 -0.00 -0.00

HIZCOJ-TS  0/ 4
Eng:  -11904.3548 -> -11904.3548, dE: 0.0000
fmax: 0.00096
time: 489.8
Strain 0.020 0.000 0.000 0.020 0.000 0.000
Stress (GPa) 0.41 0.30 0.28 0.12 -0.00 0.00

HIZCOJ-TS  1/ 0
Eng:  -11904.3112 -> -11904.3112, dE: 0.0000
fmax: 0.00100
time: 558.1
Strain 0.000 -0.020 0.000 0.000 -0.020 0.000
Stress (GPa) -0.22 -0.67 -0.17 0.00 -0.12 0.00

HIZCOJ-TS  1/ 1
Eng:  -11904.4229 -> -11904.4229, dE: 0.0000
fmax: 0.00073
time: 362.1
Strain 0.000 -0.010 0.000 0.000 -0.010 0.000
Stress (GPa) -0.07 -0.28 -0.03 0.00 -0.07 0.00

HIZCOJ-TS  1/ 2
Eng:  -11904.4536 -> -11904.4536, dE: 0.0000
fmax: 0.00092
time: 5.0
Strain 0.000 0.000 0.000 0.000 0.000 0.000
Stress (GPa) 0.08 0.07 0.08 -0.00 -0.00 0.00

HIZCOJ-TS  1/ 3
Eng:  -11904.4145 -> -11904.4145, dE: 0.0000
fmax: 0.00096
time: 415.4
Strain 0.000 0.010 0.000 0.000 0.010 0.000
Stress (GPa) 0.18 0.36 0.19 -0.00 0.06 -0.00

HIZCOJ-TS  1/ 4
Eng:  -11904.3129 -> -11904.3129, dE: 0.0000
fmax: 0.00097
time: 428.5
Strain 0.000 0.020 0.000 0.000 0.020 0.000
Stress (GPa) 0.29 0.61 0.27 0.00 0.11 -0.00

HIZCOJ-TS  2/ 0
Eng:  -11904.3700 -> -11904.3700, dE: 0.0000
fmax: 0.00098
time: 447.8
Strain 0.000 0.000 -0.020 0.000 0.000 -0.020
Stress (GPa) -0.18 -0.18 -0.41 -0.00 -0.00 -0.14

HIZCOJ-TS  2/ 1
Eng:  -11904.4423 -> -11904.4423, dE: 0.0000
fmax: 0.00081
time: 495.6
Strain 0.000 0.000 -0.010 0.000 0.000 -0.010
Stress (GPa) -0.06 -0.05 -0.14 -0.00 -0.00 -0.07

HIZCOJ-TS  2/ 2
Eng:  -11904.4536 -> -11904.4536, dE: 0.0000
fmax: 0.00092
time: 3.8
Strain 0.000 0.000 0.000 0.000 0.000 0.000
Stress (GPa) 0.08 0.07 0.08 -0.00 -0.00 0.00

HIZCOJ-TS  2/ 3
Eng:  -11904.4153 -> -11904.4153, dE: 0.0000
fmax: 0.00099
time: 300.8
Strain 0.000 0.000 0.010 0.000 0.000 0.010
Stress (GPa) 0.17 0.18 0.30 -0.00 -0.00 0.06

HIZCOJ-TS  2/ 4
Eng:  -11904.3274 -> -11904.3274, dE: 0.0000
fmax: 0.00083
time: 403.7
Strain 0.000 0.000 0.020 0.000 0.000 0.020
Stress (GPa) 0.26 0.26 0.50 0.00 0.00 0.12