File: Peptide/HIZCOJ/Detail-HIZCOJ-D3.txt
HIZCOJ-D3  0/ 0
Eng:  -11914.2866 -> -11914.2866, dE: 0.0000
fmax: 0.00083
time: 1162.6
Strain -0.020 0.000 0.000 -0.020 0.000 0.000
Stress (GPa) -0.44 -0.33 -0.26 -0.14 -0.00 0.00

HIZCOJ-D3  0/ 1
Eng:  -11914.3601 -> -11914.3601, dE: 0.0000
fmax: 0.00099
time: 396.3
Strain -0.010 0.000 0.000 -0.010 0.000 0.000
Stress (GPa) -0.24 -0.17 -0.11 -0.07 -0.00 0.00

HIZCOJ-D3  0/ 2
Eng:  -11914.3878 -> -11914.3878, dE: 0.0000
fmax: 0.00096
time: 4.0
Strain 0.000 0.000 0.000 0.000 0.000 0.000
Stress (GPa) -0.00 0.00 -0.00 -0.00 -0.00 0.00

HIZCOJ-D3  0/ 3
Eng:  -11914.3760 -> -11914.3760, dE: 0.0000
fmax: 0.00042
time: 788.6
Strain 0.010 0.000 0.000 0.010 0.000 0.000
Stress (GPa) 0.12 0.12 0.14 0.07 -0.00 -0.00

HIZCOJ-D3  0/ 4
Eng:  -11914.3197 -> -11914.3197, dE: 0.0000
fmax: 0.00070
time: 801.4
Strain 0.020 0.000 0.000 0.020 0.000 0.000
Stress (GPa) 0.28 0.24 0.24 0.14 -0.00 -0.00

HIZCOJ-D3  1/ 0
Eng:  -11914.2410 -> -11914.2410, dE: 0.0000
fmax: 0.00061
time: 792.4
Strain 0.000 -0.020 0.000 0.000 -0.020 0.000
Stress (GPa) -0.33 -0.75 -0.25 0.00 -0.07 -0.00

HIZCOJ-D3  1/ 1
Eng:  -11914.3508 -> -11914.3508, dE: 0.0000
fmax: 0.00094
time: 505.1
Strain 0.000 -0.010 0.000 0.000 -0.010 0.000
Stress (GPa) -0.18 -0.38 -0.11 0.00 -0.05 -0.00

HIZCOJ-D3  1/ 2
Eng:  -11914.3878 -> -11914.3878, dE: 0.0000
fmax: 0.00096
time: 4.0
Strain 0.000 0.000 0.000 0.000 0.000 0.000
Stress (GPa) -0.00 0.00 -0.00 -0.00 -0.00 0.00

HIZCOJ-D3  1/ 3
Eng:  -11914.3569 -> -11914.3569, dE: 0.0000
fmax: 0.00098
time: 565.1
Strain 0.000 0.010 0.000 0.000 0.010 0.000
Stress (GPa) 0.11 0.32 0.14 0.00 0.04 0.00

HIZCOJ-D3  1/ 4
Eng:  -11914.2617 -> -11914.2617, dE: 0.0000
fmax: 0.00064
time: 568.4
Strain 0.000 0.020 0.000 0.000 0.020 0.000
Stress (GPa) 0.24 0.60 0.25 -0.00 0.08 -0.00

HIZCOJ-D3  2/ 0
Eng:  -11914.2750 -> -11914.2750, dE: 0.0000
fmax: 0.00091
time: 550.8
Strain 0.000 0.000 -0.020 0.000 0.000 -0.020
Stress (GPa) -0.30 -0.30 -0.55 0.00 -0.00 -0.14

HIZCOJ-D3  2/ 1
Eng:  -11914.3636 -> -11914.3636, dE: 0.0000
fmax: 0.00074
time: 496.9
Strain 0.000 0.000 -0.010 0.000 0.000 -0.010
Stress (GPa) -0.16 -0.14 -0.25 -0.00 0.00 -0.06

HIZCOJ-D3  2/ 2
Eng:  -11914.3878 -> -11914.3878, dE: 0.0000
fmax: 0.00096
time: 4.1
Strain 0.000 0.000 0.000 0.000 0.000 0.000
Stress (GPa) -0.00 0.00 -0.00 -0.00 -0.00 0.00

HIZCOJ-D3  2/ 3
Eng:  -11914.3573 -> -11914.3573, dE: 0.0000
fmax: 0.00091
time: 347.8
Strain 0.000 0.000 0.010 0.000 0.000 0.010
Stress (GPa) 0.10 0.12 0.26 0.00 -0.00 0.06

HIZCOJ-D3  2/ 4
Eng:  -11914.2768 -> -11914.2768, dE: 0.0000
fmax: 0.00095
time: 467.4
Strain 0.000 0.000 0.020 0.000 0.000 0.020
Stress (GPa) 0.20 0.22 0.48 0.00 -0.00 0.11