File: Peptide_dh/ETIWIN/Detail-ETIWIN-TS.txt
ETIWIN-TS  0/ 0
Eng:  -29011.3508 -> -29011.3508, dE: 0.0000
fmax: 0.00099
time: 5215.7
Strain 0.000 0.000 -0.020 0.000 0.000 0.000
Stress (GPa) -0.14 -0.07 -0.26 0.00 0.00 0.00

ETIWIN-TS  0/ 1
Eng:  -29011.4540 -> -29011.4540, dE: 0.0000
fmax: 0.00088
time: 2586.8
Strain 0.000 0.000 -0.010 0.000 0.000 0.000
Stress (GPa) -0.06 -0.01 -0.12 -0.00 0.00 -0.00

ETIWIN-TS  0/ 2
Eng:  -29011.4799 -> -29011.4799, dE: 0.0000
fmax: 0.00089
time: 16.8
Strain 0.000 0.000 0.000 0.000 0.000 0.000
Stress (GPa) 0.00 0.00 0.01 0.00 0.00 0.00

ETIWIN-TS  0/ 3
Eng:  -29011.4507 -> -29011.4507, dE: 0.0000
fmax: 0.00095
time: 1933.5
Strain 0.000 0.000 0.010 0.000 0.000 0.000
Stress (GPa) 0.07 0.08 0.14 0.00 0.00 -0.01

ETIWIN-TS  0/ 4
Eng:  -29011.3547 -> -29011.3547, dE: 0.0000
fmax: 0.00096
time: 2386.9
Strain 0.000 0.000 0.020 0.000 0.000 0.000
Stress (GPa) 0.13 0.13 0.25 0.00 0.00 -0.01

ETIWIN-TS  1/ 0
Eng:  -29011.4093 -> -29011.4093, dE: 0.0000
fmax: 0.00635
time: 5099.5
Strain -0.020 0.000 0.000 -0.020 0.000 0.000
Stress (GPa) -0.19 -0.03 -0.13 -0.03 0.01 -0.00

ETIWIN-TS  1/ 1
Eng:  -29011.4564 -> -29011.4564, dE: 0.0000
fmax: 0.00085
time: 2686.7
Strain -0.010 0.000 0.000 -0.010 0.000 0.000
Stress (GPa) -0.10 -0.00 -0.06 -0.02 0.00 -0.01

ETIWIN-TS  1/ 2
Eng:  -29011.4799 -> -29011.4799, dE: 0.0000
fmax: 0.00089
time: 16.4
Strain 0.000 0.000 0.000 0.000 0.000 0.000
Stress (GPa) 0.00 0.00 0.01 0.00 0.00 0.00

ETIWIN-TS  1/ 3
Eng:  -29011.4490 -> -29011.4490, dE: 0.0000
fmax: 0.00097
time: 2591.4
Strain 0.010 0.000 0.000 0.010 0.000 0.000
Stress (GPa) 0.12 0.08 0.07 0.02 -0.00 -0.01

ETIWIN-TS  1/ 4
Eng:  -29011.3452 -> -29011.3452, dE: 0.0000
fmax: 0.00092
time: 2916.1
Strain 0.020 0.000 0.000 0.020 0.000 0.000
Stress (GPa) 0.23 0.12 0.12 0.04 0.00 -0.00

ETIWIN-TS  2/ 0
Eng:  -29011.3787 -> -29011.3787, dE: 0.0000
fmax: 0.00094
time: 2716.5
Strain -0.020 0.000 0.000 0.000 0.000 0.000
Stress (GPa) -0.22 -0.05 -0.15 -0.00 -0.00 -0.01

ETIWIN-TS  2/ 1
Eng:  -29011.4610 -> -29011.4610, dE: 0.0000
fmax: 0.00081
time: 2563.4
Strain -0.010 0.000 0.000 0.000 0.000 0.000
Stress (GPa) -0.11 -0.01 -0.07 0.00 0.00 -0.01

ETIWIN-TS  2/ 2
Eng:  -29011.4799 -> -29011.4799, dE: 0.0000
fmax: 0.00089
time: 16.5
Strain 0.000 0.000 0.000 0.000 0.000 0.000
Stress (GPa) 0.00 0.00 0.01 0.00 0.00 0.00

ETIWIN-TS  2/ 3
Eng:  -29011.4543 -> -29011.4543, dE: 0.0000
fmax: 0.00090
time: 2495.6
Strain 0.010 0.000 0.000 0.000 0.000 0.000
Stress (GPa) 0.13 0.08 0.07 -0.00 0.00 -0.01

ETIWIN-TS  2/ 4
Eng:  -29011.3610 -> -29011.3610, dE: 0.0000
fmax: 0.00099
time: 2481.7
Strain 0.020 0.000 0.000 0.000 0.000 0.000
Stress (GPa) 0.24 0.12 0.12 0.00 0.00 -0.00

ETIWIN-TS  3/ 0
Eng:  -29011.3292 -> -29011.3292, dE: 0.0000
fmax: 0.00100
time: 2673.5
Strain 0.000 0.000 -0.020 -0.020 0.000 0.000
Stress (GPa) -0.14 -0.07 -0.26 -0.04 0.01 0.00

ETIWIN-TS  3/ 1
Eng:  -29011.4488 -> -29011.4488, dE: 0.0000
fmax: 0.00100
time: 2728.4
Strain 0.000 0.000 -0.010 -0.010 0.000 0.000
Stress (GPa) -0.06 -0.01 -0.12 -0.02 0.00 -0.00

ETIWIN-TS  3/ 2
Eng:  -29011.4799 -> -29011.4799, dE: 0.0000
fmax: 0.00089
time: 16.4
Strain 0.000 0.000 0.000 0.000 0.000 0.000
Stress (GPa) 0.00 0.00 0.01 0.00 0.00 0.00

ETIWIN-TS  3/ 3
Eng:  -29011.4450 -> -29011.4450, dE: 0.0000
fmax: 0.00099
time: 2147.7
Strain 0.000 0.000 0.010 0.010 0.000 0.000
Stress (GPa) 0.07 0.08 0.14 0.03 -0.00 -0.01

ETIWIN-TS  3/ 4
Eng:  -29011.3361 -> -29011.3361, dE: 0.0000
fmax: 0.00100
time: 2815.7
Strain 0.000 0.000 0.020 0.020 0.000 0.000
Stress (GPa) 0.13 0.13 0.25 0.05 0.00 -0.01